<robot
  name="bamba">
  <link
    name="base">
    <inertial>
      <origin
        xyz="-1.3286E-17 0.010522 -2.0071E-19"
        rpy="0 0 0" />
      <mass
        value="7.4968" />
      <inertia
        ixx="0.001"
        ixy="0"
        ixz="0"
        iyy="0.001"
        iyz="0"
        izz="0.001" />
    </inertial>
    <visual>
      <origin
        xyz="0 0 0"
        rpy="0 0 0" />
      <geometry>
        <mesh
          filename="package://bamba/meshes/base.STL" />
      </geometry>
      <material
        name="">
        <color
          rgba="1 1 1 1" />
      </material>
    </visual>
    <collision>
      <origin
        xyz="0 0 0"
        rpy="0 0 0" />
      <geometry>
        <mesh
          filename="package://bamba/meshes/base.STL" />
      </geometry>
    </collision>
  </link>
  <link
    name="base_link">
    <inertial>
      <origin
        xyz="-0.029653 -0.00012697 0.0013008"
        rpy="0 0 0" />
      <mass
        value="0.13356" />
      <inertia
        ixx="0.001"
        ixy="0"
        ixz="0"
        iyy="0.001"
        iyz="0"
        izz="0.001" />
    </inertial>
    <visual>
      <origin
        xyz="0 0 0"
        rpy="0 0 0" />
      <geometry>
        <mesh
          filename="package://bamba/meshes/base_link.STL" />
      </geometry>
      <material
        name="">
        <color
          rgba="0.64706 0.61961 0.58824 1" />
      </material>
    </visual>
    <collision>
      <origin
        xyz="0 0 0"
        rpy="0 0 0" />
      <geometry>
        <mesh
          filename="package://bamba/meshes/base_link.STL" />
      </geometry>
    </collision>
  </link>
  <joint
    name="joint_0"
    type="revolute">
    <origin
      xyz="0 0 0.044"
      rpy="1.4709 1.5708 0" />
    <parent
      link="base" />
    <child
      link="base_link" />
    <axis
      xyz="-1 0 0" />
    <limit
      lower="-1.57"
      upper="1.57"
      effort="100"
      velocity="100" />
    <dynamics
      damping="1"
      friction="1" />
  </joint>
  <link
    name="link_1">
    <inertial>
      <origin
        xyz="-0.00012583 0.03094 0.0017334"
        rpy="0 0 0" />
      <mass
        value="0.040392" />
      <inertia
        ixx="0.001"
        ixy="0"
        ixz="0"
        iyy="0.001"
        iyz="0"
        izz="0.001" />
    </inertial>
    <visual>
      <origin
        xyz="0 0 0"
        rpy="0 0 0" />
      <geometry>
        <mesh
          filename="package://bamba/meshes/link_1.STL" />
      </geometry>
      <material
        name="">
        <color
          rgba="0.89804 0.91765 0.92941 1" />
      </material>
    </visual>
    <collision>
      <origin
        xyz="0 0 0"
        rpy="0 0 0" />
      <geometry>
        <mesh
          filename="package://bamba/meshes/link_1.STL" />
      </geometry>
    </collision>
  </link>
  <joint
    name="joint_1"
    type="revolute">
    <origin
      xyz="-0.038 0 0"
      rpy="-1.6121E-17 -0.0973 1.5708" />
    <parent
      link="base_link" />
    <child
      link="link_1" />
    <axis
      xyz="0 0 1" />
    <limit
      lower="-1.77"
      upper="1.77"
      effort="100"
      velocity="100" />
    <dynamics
      damping="1"
      friction="1" />
  </joint>
  <link
    name="link_2">
    <inertial>
      <origin
        xyz="-0.02101 -0.0012662 0.0017342"
        rpy="0 0 0" />
      <mass
        value="0.036964" />
      <inertia
        ixx="0.001"
        ixy="0"
        ixz="0"
        iyy="0.001"
        iyz="0"
        izz="0.001" />
    </inertial>
    <visual>
      <origin
        xyz="0 0 0"
        rpy="0 0 0" />
      <geometry>
        <mesh
          filename="package://bamba/meshes/link_2.STL" />
      </geometry>
      <material
        name="">
        <color
          rgba="0.89804 0.91765 0.92941 1" />
      </material>
    </visual>
    <collision>
      <origin
        xyz="0 0 0"
        rpy="0 0 0" />
      <geometry>
        <mesh
          filename="package://bamba/meshes/link_2.STL" />
      </geometry>
    </collision>
  </link>
  <joint
    name="joint_2"
    type="revolute">
    <origin
      xyz="-0.00027654 0.067999 0"
      rpy="8.9772E-17 8.3728E-17 -1.6363" />
    <parent
      link="link_1" />
    <child
      link="link_2" />
    <axis
      xyz="0 0 1" />
    <limit
      lower="-1.77"
      upper="1.77"
      effort="100"
      velocity="100" />
    <dynamics
      damping="1"
      friction="1" />
  </joint>
  <link
    name="link_3">
    <inertial>
      <origin
        xyz="-0.0091402 0.01896 0.0017334"
        rpy="0 0 0" />
      <mass
        value="0.036964" />
      <inertia
        ixx="0.001"
        ixy="0"
        ixz="0"
        iyy="0.001"
        iyz="0"
        izz="0.001" />
    </inertial>
    <visual>
      <origin
        xyz="0 0 0"
        rpy="0 0 0" />
      <geometry>
        <mesh
          filename="package://bamba/meshes/link_3.STL" />
      </geometry>
      <material
        name="">
        <color
          rgba="0.89804 0.91765 0.92941 1" />
      </material>
    </visual>
    <collision>
      <origin
        xyz="0 0 0"
        rpy="0 0 0" />
      <geometry>
        <mesh
          filename="package://bamba/meshes/link_3.STL" />
      </geometry>
    </collision>
  </link>
  <joint
    name="joint_3"
    type="revolute">
    <origin
      xyz="-0.052405 -0.0031609 0"
      rpy="-1.0603E-16 -2.6455E-17 1.1761" />
    <parent
      link="link_2" />
    <child
      link="link_3" />
    <axis
      xyz="0 0 1" />
    <limit
      lower="-1.77"
      upper="1.77"
      effort="100"
      velocity="100" />
    <dynamics
      damping="1"
      friction="1" />
  </joint>
  <link
    name="link_4">
    <inertial>
      <origin
        xyz="-0.010775 0.011369 0.0018811"
        rpy="0 0 0" />
      <mass
        value="0.03322" />
      <inertia
        ixx="0.001"
        ixy="0"
        ixz="0"
        iyy="0.001"
        iyz="0"
        izz="0.001" />
    </inertial>
    <visual>
      <origin
        xyz="0 0 0"
        rpy="0 0 0" />
      <geometry>
        <mesh
          filename="package://bamba/meshes/link_4.STL" />
      </geometry>
      <material
        name="">
        <color
          rgba="0.89804 0.91765 0.92941 1" />
      </material>
    </visual>
    <collision>
      <origin
        xyz="0 0 0"
        rpy="0 0 0" />
      <geometry>
        <mesh
          filename="package://bamba/meshes/link_4.STL" />
      </geometry>
    </collision>
  </link>
  <joint
    name="joint_4"
    type="revolute">
    <origin
      xyz="-0.022802 0.04729 0"
      rpy="-1.7347E-18 0 -0.30764" />
    <parent
      link="link_3" />
    <child
      link="link_4" />
    <axis
      xyz="0 0 1" />
    <limit
      lower="-1.77"
      upper="1.77"
      effort="100"
      velocity="100" />
    <dynamics
      damping="1"
      friction="1" />
  </joint>
  <link
    name="pincer_master">
    <inertial>
      <origin
        xyz="0.0046223 -0.010473 0.00013126"
        rpy="0 0 0" />
      <mass
        value="0.0047634" />
      <inertia
        ixx="0.001"
        ixy="0"
        ixz="0"
        iyy="0.001"
        iyz="0"
        izz="0.001" />
    </inertial>
    <visual>
      <origin
        xyz="0 0 0"
        rpy="0 0 0" />
      <geometry>
        <mesh
          filename="package://bamba/meshes/pincer_master.STL" />
      </geometry>
      <material
        name="">
        <color
          rgba="0.89804 0.91765 0.92941 1" />
      </material>
    </visual>
    <collision>
      <origin
        xyz="0 0 0"
        rpy="0 0 0" />
      <geometry>
        <mesh
          filename="package://bamba/meshes/pincer_master.STL" />
      </geometry>
    </collision>
  </link>
  <joint
    name="joint_5"
    type="revolute">
    <origin
      xyz="-0.0227 0.023952 0.0064819"
      rpy="0.076967 -2.2708E-15 -2.383" />
    <parent
      link="link_4" />
    <child
      link="pincer_master" />
    <axis
      xyz="-1 0 0" />
    <limit
      lower="0"
      upper="3.14"
      effort="100"
      velocity="100" />
    <dynamics
      damping="1"
      friction="1" />
  </joint>
  <link
    name="pincer_slave">
    <inertial>
      <origin
        xyz="0.0046223 -0.010408 -0.0011652"
        rpy="0 0 0" />
      <mass
        value="0.0047634" />
      <inertia
        ixx="0.001"
        ixy="0"
        ixz="0"
        iyy="0.001"
        iyz="0"
        izz="0.001" />
    </inertial>
    <visual>
      <origin
        xyz="0 0 0"
        rpy="0 0 0" />
      <geometry>
        <mesh
          filename="package://bamba/meshes/pincer_slave.STL" />
      </geometry>
      <material
        name="">
        <color
          rgba="0.89804 0.91765 0.92941 1" />
      </material>
    </visual>
    <collision>
      <origin
        xyz="0 0 0"
        rpy="0 0 0" />
      <geometry>
        <mesh
          filename="package://bamba/meshes/pincer_slave.STL" />
      </geometry>
    </collision>
  </link>
  <joint
    name="joint_slave"
    type="revolute">
    <origin
      xyz="-0.0227 0.023952 -0.0088681"
      rpy="0.076967 -2.2708E-15 -2.383" />
    <parent
      link="link_4" />
    <child
      link="pincer_slave" />
    <axis
      xyz="-1 0 0" />
    <limit
      lower="-3.14"
      upper="0"
      effort="100"
      velocity="100" />
    <dynamics
      damping="1"
      friction="1" />
  </joint>
</robot>
